Workbook
Name Slicer_Campaign_Name: #N/A
Name Slicer_Campaign_Name1: #N/A
Name Slicer_Campaign_Name2: #N/A
Name Slicer_Platform: #N/A

Sheet Posts 
A1: Post ID | B1: Platform | C1: Date | D1: Content Type | E1: Post Text | F1: Likes | G1: Shares | H1: Comments | I1: Impressions | J1: Reach | K1: Clicks | L1: Hashtags Used.1 | M1: Hashtags Used.2 | N1: Hashtags Used.3 | O1: Campaign_Name | P1: Engagement Rate | Q1: Hashtags | R1: Start Date | S1: End Date | T1: Period | U1: Engagement | V1: Before | W1: During | X1: Uplift | Y1: Total Budget | Z1: ROI | AA1: UPLIFT %
A2: P001 | B2: X | C2: 45649 | D2: Reel | E2: Check out our latest reel on twitter! | F2: 1461 | G2: 184 | H2: 344 | I2: 21915 | J2: 21675 | K2: 15 | L2: #FutureOfDriving | M2: #AnytimeIsTeslaTime | O2: CybertruckLaunch | P2: =IFERROR(((Posts_Cleaned[[#This Row],[Likes]]+Posts_Cleaned[[#This Row],[Shares]]+Posts_Cleaned[[#This Row],[Comments]])/Posts_Cleaned[[#This Row],[Impressions]]),0) -> 0.090759754 | Q2: =_xlfn.TEXTJOIN(", ", TRUE, Posts_Cleaned[[#This Row],[Hashtags Used.1]], Posts_Cleaned[[#This Row],[Hashtags Used.2]], Posts_Cleaned[[#This Row],[Hashtags Used.3]]) -> #FutureOfDriving, #AnytimeIsTeslaTime | R2: =VLOOKUP(Posts_Cleaned[[#This Row],[Campaign_Name]],'Campaign Metadata Dataset '!$A$2:$B$5,2,0) -> 45458 | S2: =VLOOKUP(Posts_Cleaned[[#This Row],[Campaign_Name]],'Campaign Metadata Dataset '!$A$1:$C$5,3,0) -> 45488 | T2: =IF(AND(C2>R2, C2<=S2),"During Campaign","Before Campaign") -> Before Campaign | U2: =SUM(Posts_Cleaned[[#This Row],[Likes]]+Posts_Cleaned[[#This Row],[Shares]]+Posts_Cleaned[[#This Row],[Comments]]+Posts_Cleaned[[#This Row],[Clicks]]) -> 2004 | V2: =AVERAGEIF(Posts_Cleaned[[#This Row],[Period]]:T:T,"Before Campaign",Posts_Cleaned[[#This Row],[Engagement Rate ]]) -> 0.14581846 | W2: =AVERAGEIF($T$2:$T$302,"During Campaign",P2) -> 0.12852412 | X2: =(W2-V2)/W2 -> -0.13456104 | Y2: =IFERROR(VLOOKUP(O2, 'Campaign Metadata Dataset '!$A$1:$G$5,5,0),0) -> 150000 | Z2: =(Posts_Cleaned[[#This Row],[Likes]]+Posts_Cleaned[[#This Row],[Shares]]+Posts_Cleaned[[#This Row],[Comments]]+Posts_Cleaned[[#This Row],[Clicks]])/Posts_Cleaned[[#This Row],[Total Budget ]] -> 0.01336 | AA2: =(W:W-V:V)/W:W -> -0.13456104
A3: P002 | B3: X | C3: 45750 | D3: Text | E3: Check out our latest text on twitter! | F3: 4054 | G3: 389 | H3: 493 | I3: 64864 | J3: 64383 | K3: 117 | L3: #TeslaCoInnovation | M3: #BetterWithTesla | O3: ModelYCampaign | P3: =IFERROR(((Posts_Cleaned[[#This Row],[Likes]]+Posts_Cleaned[[#This Row],[Shares]]+Posts_Cleaned[[#This Row],[Comments]])/Posts_Cleaned[[#This Row],[Impressions]]),0) -> 0.076097681 | Q3: =_xlfn.TEXTJOIN(", ", TRUE, Posts_Cleaned[[#This Row],[Hashtags Used.1]], Posts_Cleaned[[#This Row],[Hashtags Used.2]], Posts_Cleaned[[#This Row],[Hashtags Used.3]]) -> #TeslaCoInnovation, #BetterWithTesla | R3: =VLOOKUP(Posts_Cleaned[[#This Row],[Campaign_Name]],'Campaign Metadata Dataset '!$A$2:$B$5,2,0) -> 45566 | S3: =VLOOKUP(Posts_Cleaned[[#This Row],[Campaign_Name]],'Campaign Metadata Dataset '!$A$1:$C$5,3,0) -> 45596 | T3: =IF(AND(C3>R3, C3<=S3),"During Campaign","Before Campaign") -> Before Campaign | U3: =SUM(Posts_Cleaned[[#This Row],[Likes]]+Posts_Cleaned[[#This Row],[Shares]]+Posts_Cleaned[[#This Row],[Comments]]+Posts_Cleaned[[#This Row],[Clicks]]) -> 5053 | V3: =AVERAGEIF(Posts_Cleaned[[#This Row],[Period]]:T:T,"Before Campaign",Posts_Cleaned[[#This Row],[Engagement Rate ]]) -> 0.14572925 | W3: =AVERAGEIF($T$2:$T$302,"During Campaign",P3) -> 0.18027698 | X3: =(Posts_Cleaned[[#This Row],[During ]]-Posts_Cleaned[[#This Row],[Before ]])/Posts_Cleaned[[#This Row],[During ]] -> 0.19163697 | Y3: =IFERROR(VLOOKUP(O3, 'Campaign Metadata Dataset '!$A$1:$G$5,5,0),0) -> 200000 | Z3: =(F:F+G:G+H:H+K:K)/Y:Y -> 0.025265 | AA3: =(W:W-V:V)/W:W -> 0.19163697
A4: P003 | B4: YouTube | C4: 45789 | D4: Reel | E4: Check out our latest reel on youtube! | F4: 2795 | G4: 105 | H4: 49 | I4: 53105 | J4: 52307 | K4: 204 | L4: #TeslaCoInnovation | O4: FSDUpdate | P4: =IFERROR(((Posts_Cleaned[[#This Row],[Likes]]+Posts_Cleaned[[#This Row],[Shares]]+Posts_Cleaned[[#This Row],[Comments]])/Posts_Cleaned[[#This Row],[Impressions]]),0) -> 0.055531494 | Q4: =_xlfn.TEXTJOIN(", ", TRUE, Posts_Cleaned[[#This Row],[Hashtags Used.1]], Posts_Cleaned[[#This Row],[Hashtags Used.2]], Posts_Cleaned[[#This Row],[Hashtags Used.3]]) -> #TeslaCoInnovation | R4: =VLOOKUP(Posts_Cleaned[[#This Row],[Campaign_Name]],'Campaign Metadata Dataset '!$A$2:$B$5,2,0) -> 45651 | S4: =VLOOKUP(Posts_Cleaned[[#This Row],[Campaign_Name]],'Campaign Metadata Dataset '!$A$1:$C$5,3,0) -> 45667 | T4: =IF(AND(C4>R4, C4<=S4),"During Campaign","Before Campaign") -> Before Campaign | U4: =SUM(Posts_Cleaned[[#This Row],[Likes]]+Posts_Cleaned[[#This Row],[Shares]]+Posts_Cleaned[[#This Row],[Comments]]+Posts_Cleaned[[#This Row],[Clicks]]) -> 3153 | V4: =AVERAGEIF(Posts_Cleaned[[#This Row],[Period]]:T:T,"Before Campaign",Posts_Cleaned[[#This Row],[Engagement Rate ]]) -> 0.14082149 | W4: =AVERAGEIF($T$2:$T$302,"During Campaign",P4) -> 0.16154791 | X4: =(Posts_Cleaned[[#This Row],[During ]]-Posts_Cleaned[[#This Row],[Before ]])/Posts_Cleaned[[#This Row],[During ]] -> 0.12829894 | Y4: =IFERROR(VLOOKUP(O4, 'Campaign Metadata Dataset '!$A$1:$G$5,5,0),0) -> 250000 | Z4: =(F:F+G:G+H:H+K:K)/Y:Y -> 0.012612 | AA4: =(W:W-V:V)/W:W -> 0.12829894
A5: P004 | B5: Instagram | C5: 45516 | D5: Story | E5: Check out our latest story on instagram! | F5: 2404 | G5: 363 | H5: 138 | I5: 19232 | J5: 18636 | K5: 128 | L5: #EVRevolution | O5: SustainabilityDrive | P5: =IFERROR(((Posts_Cleaned[[#This Row],[Likes]]+Posts_Cleaned[[#This Row],[Shares]]+Posts_Cleaned[[#This Row],[Comments]])/Posts_Cleaned[[#This Row],[Impressions]]),0) -> 0.15105033 | Q5: =_xlfn.TEXTJOIN(", ", TRUE, Posts_Cleaned[[#This Row],[Hashtags Used.1]], Posts_Cleaned[[#This Row],[Hashtags Used.2]], Posts_Cleaned[[#This Row],[Hashtags Used.3]]) -> #EVRevolution | R5: =VLOOKUP(Posts_Cleaned[[#This Row],[Campaign_Name]],'Campaign Metadata Dataset '!$A$2:$B$5,2,0) -> 45717 | S5: =VLOOKUP(Posts_Cleaned[[#This Row],[Campaign_Name]],'Campaign Metadata Dataset '!$A$1:$C$5,3,0) -> 45747 | T5: =IF(AND(C5>R5, C5<=S5),"During Campaign","Before Campaign") -> Before Campaign | U5: =SUM(Posts_Cleaned[[#This Row],[Likes]]+Posts_Cleaned[[#This Row],[Shares]]+Posts_Cleaned[[#This Row],[Comments]]+Posts_Cleaned[[#This Row],[Clicks]]) -> 3033 | V5: =AVERAGEIF(Posts_Cleaned[[#This Row],[Period]]:T:T,"Before Campaign",Posts_Cleaned[[#This Row],[Engagement Rate ]]) -> 0.15032951 | W5: =AVERAGEIF($T$2:$T$302,"During Campaign",P5) -> 0.14598514 | X5: =(Posts_Cleaned[[#This Row],[During ]]-Posts_Cleaned[[#This Row],[Before ]])/Posts_Cleaned[[#This Row],[During ]] -> -0.029758991 | Y5: =IFERROR(VLOOKUP(O5, 'Campaign Metadata Dataset '!$A$1:$G$5,5,0),0) -> 180000 | Z5: =(F:F+G:G+H:H+K:K)/Y:Y -> 0.01685 | AA5: =(W:W-V:V)/W:W -> -0.029758991
A6: P005 | B6: YouTube | C6: 45469 | D6: Reel | E6: Check out our latest reel on youtube! | F6: 3557 | G6: 687 | H6: 424 | I6: 71140 | J6: 70701 | K6: 224 | L6: #EVRevolution | M6: #TeslaCoInnovation | O6: CybertruckLaunch | P6: =IFERROR(((Posts_Cleaned[[#This Row],[Likes]]+Posts_Cleaned[[#This Row],[Shares]]+Posts_Cleaned[[#This Row],[Comments]])/Posts_Cleaned[[#This Row],[Impressions]]),0) -> 0.065617093 | Q6: =_xlfn.TEXTJOIN(", ", TRUE, Posts_Cleaned[[#This Row],[Hashtags Used.1]], Posts_Cleaned[[#This Row],[Hashtags Used.2]], Posts_Cleaned[[#This Row],[Hashtags Used.3]]) -> #EVRevolution, #TeslaCoInnovation | R6: =VLOOKUP(Posts_Cleaned[[#This Row],[Campaign_Name]],'Campaign Metadata Dataset '!$A$2:$B$5,2,0) -> 45458 | S6: =VLOOKUP(Posts_Cleaned[[#This Row],[Campaign_Name]],'Campaign Metadata Dataset '!$A$1:$C$5,3,0) -> 45488 | T6: =IF(AND(C6>R6, C6<=S6),"During Campaign","Before Campaign") -> During Campaign | U6: =SUM(Posts_Cleaned[[#This Row],[Likes]]+Posts_Cleaned[[#This Row],[Shares]]+Posts_Cleaned[[#This Row],[Comments]]+Posts_Cleaned[[#This Row],[Clicks]]) -> 4892 | V6: =AVERAGEIF(Posts_Cleaned[[#This Row],[Period]]:T:T,"Before Campaign",Posts_Cleaned[[#This Row],[Engagement Rate ]]) -> 0.14805747 | W6: =AVERAGEIF($T$2:$T$302,"During Campaign",P6) -> 0.15787463 | X6: =(Posts_Cleaned[[#This Row],[During ]]-Posts_Cleaned[[#This Row],[Before ]])/Posts_Cleaned[[#This Row],[During ]] -> 0.062183265 | Y6: =IFERROR(VLOOKUP(O6, 'Campaign Metadata Dataset '!$A$1:$G$5,5,0),0) -> 150000 | Z6: =(F:F+G:G+H:H+K:K)/Y:Y -> 0.032613333 | AA6: =(W:W-V:V)/W:W -> 0.062183265
A7: P006 | B7: Facebook | C7: 45596 | D7: Carousel | E7: Check out our latest carousel on facebook! | F7: 2945 | G7: 930 | H7: 355 | I7: 23560 | J7: 23275 | K7: 256 | L7: #TeslaCoInnovation | O7: ModelYCampaign | P7: =IFERROR(((Posts_Cleaned[[#This Row],[Likes]]+Posts_Cleaned[[#This Row],[Shares]]+Posts_Cleaned[[#This Row],[Comments]])/Posts_Cleaned[[#This Row],[Impressions]]),0) -> 0.1795416 | Q7: =_xlfn.TEXTJOIN(", ", TRUE, Posts_Cleaned[[#This Row],[Hashtags Used.1]], Posts_Cleaned[[#This Row],[Hashtags Used.2]], Posts_Cleaned[[#This Row],[Hashtags Used.3]]) -> #TeslaCoInnovation | R7: =VLOOKUP(Posts_Cleaned[[#This Row],[Campaign_Name]],'Campaign Metadata Dataset '!$A$2:$B$5,2,0) -> 45566 | S7: =VLOOKUP(Posts_Cleaned[[#This Row],[Campaign_Name]],'Campaign Metadata Dataset '!$A$1:$C$5,3,0) -> 45596 | T7: =IF(AND(C7>R7, C7<=S7),"During Campaign","Before Campaign") -> During Campaign | U7: =SUM(Posts_Cleaned[[#This Row],[Likes]]+Posts_Cleaned[[#This Row],[Shares]]+Posts_Cleaned[[#This Row],[Comments]]+Posts_Cleaned[[#This Row],[Clicks]]) -> 4486 | V7: =AVERAGEIF(Posts_Cleaned[[#This Row],[Period]]:T:T,"Before Campaign",Posts_Cleaned[[#This Row],[Engagement Rate ]]) -> 0.14973769 | W7: =AVERAGEIF($T$2:$T$302,"During Campaign",P7) -> 0.14999161 | X7: =(Posts_Cleaned[[#This Row],[During ]]-Posts_Cleaned[[#This Row],[Before ]])/Posts_Cleaned[[#This Row],[During ]] -> 0.0016928592 | Y7: =IFERROR(VLOOKUP(O7, 'Campaign Metadata Dataset '!$A$1:$G$5,5,0),0) -> 200000 | Z7: =(F:F+G:G+H:H+K:K)/Y:Y -> 0.02243 | AA7: =(W:W-V:V)/W:W -> 0.0016928592
A8: P007 | B8: X | C8: 45467 | D8: Carousel | E8: Check out our latest carousel on twitter! | F8: 3860 | G8: 201 | H8: 279 | I8: 61760 | J8: 61660 | K8: 235 | L8: #TeslaCoInnovation | O8: ModelYCampaign | P8: =IFERROR(((Posts_Cleaned[[#This Row],[Likes]]+Posts_Cleaned[[#This Row],[Shares]]+Posts_Cleaned[[#This Row],[Comments]])/Posts_Cleaned[[#This Row],[Impressions]]),0) -> 0.070272021 | Q8: =_xlfn.TEXTJOIN(", ", TRUE, Posts_Cleaned[[#This Row],[Hashtags Used.1]], Posts_Cleaned[[#This Row],[Hashtags Used.2]], Posts_Cleaned[[#This Row],[Hashtags Used.3]]) -> #TeslaCoInnovation | R8: =VLOOKUP(Posts_Cleaned[[#This Row],[Campaign_Name]],'Campaign Metadata Dataset '!$A$2:$B$5,2,0) -> 45566 | S8: =VLOOKUP(Posts_Cleaned[[#This Row],[Campaign_Name]],'Campaign Metadata Dataset '!$A$1:$C$5,3,0) -> 45596 | T8: =IF(AND(C8>R8, C8<=S8),"During Campaign","Before Campaign") -> Before Campaign | U8: =SUM(Posts_Cleaned[[#This Row],[Likes]]+Posts_Cleaned[[#This Row],[Shares]]+Posts_Cleaned[[#This Row],[Comments]]+Posts_Cleaned[[#This Row],[Clicks]]) -> 4575 | V8: =AVERAGEIF(Posts_Cleaned[[#This Row],[Period]]:T:T,"Before Campaign",Posts_Cleaned[[#This Row],[Engagement Rate ]]) -> 0.15113022 | W8: =AVERAGEIF($T$2:$T$302,"During Campaign",P8) -> 0.15368622 | X8: =(Posts_Cleaned[[#This Row],[During ]]-Posts_Cleaned[[#This Row],[Before ]])/Posts_Cleaned[[#This Row],[During ]] -> 0.016631289 | Y8: =IFERROR(VLOOKUP(O8, 'Campaign Metadata Dataset '!$A$1:$G$5,5,0),0) -> 200000 | Z8: =(F:F+G:G+H:H+K:K)/Y:Y -> 0.022875 | AA8: =(W:W-V:V)/W:W -> 0.016631289
A9: P008 | B9: YouTube | C9: 45486 | D9: Image | E9: Check out our latest image on youtube! | F9: 3929 | G9: 262 | H9: 278 | I9: 43219 | J9: 42841 | K9: 39 | L9: #EVRevolution | O9: SustainabilityDrive | P9: =IFERROR(((Posts_Cleaned[[#This Row],[Likes]]+Posts_Cleaned[[#This Row],[Shares]]+Posts_Cleaned[[#This Row],[Comments]])/Posts_Cleaned[[#This Row],[Impressions]]),0) -> 0.1034036 | Q9: =_xlfn.TEXTJOIN(", ", TRUE, Posts_Cleaned[[#This Row],[Hashtags Used.1]], Posts_Cleaned[[#This Row],[Hashtags Used.2]], Posts_Cleaned[[#This Row],[Hashtags Used.3]]) -> #EVRevolution | R9: =VLOOKUP(Posts_Cleaned[[#This Row],[Campaign_Name]],'Campaign Metadata Dataset '!$A$2:$B$5,2,0) -> 45717 | S9: =VLOOKUP(Posts_Cleaned[[#This Row],[Campaign_Name]],'Campaign Metadata Dataset '!$A$1:$C$5,3,0) -> 45747 | T9: =IF(AND(C9>R9, C9<=S9),"During Campaign","Before Campaign") -> Before Campaign | U9: =SUM(Posts_Cleaned[[#This Row],[Likes]]+Posts_Cleaned[[#This Row],[Shares]]+Posts_Cleaned[[#This Row],[Comments]]+Posts_Cleaned[[#This Row],[Clicks]]) -> 4508 | V9: =AVERAGEIF(Posts_Cleaned[[#This Row],[Period]]:T:T,"Before Campaign",Posts_Cleaned[[#This Row],[Engagement Rate ]]) -> 0.15662962 | W9: =AVERAGEIF($T$2:$T$302,"During Campaign",P9) -> 0.14010367 | X9: =(Posts_Cleaned[[#This Row],[During ]]-Posts_Cleaned[[#This Row],[Before ]])/Posts_Cleaned[[#This Row],[During ]] -> -0.11795518 | Y9: =IFERROR(VLOOKUP(O9, 'Campaign Metadata Dataset '!$A$1:$G$5,5,0),0) -> 180000 | Z9: =(F:F+G:G+H:H+K:K)/Y:Y -> 0.025044444 | AA9: =(W:W-V:V)/W:W -> -0.11795518
A10: P009 | B10: Facebook | C10: 45534 | D10: Text | E10: Check out our latest text on facebook! | F10: 3784 | G10: 808 | H10: 404 | I10: 56760 | J10: 56343 | K10: 131 | L10: #TeslaCoInnovation | O10: ModelYCampaign | P10: =IFERROR(((Posts_Cleaned[[#This Row],[Likes]]+Posts_Cleaned[[#This Row],[Shares]]+Posts_Cleaned[[#This Row],[Comments]])/Posts_Cleaned[[#This Row],[Impressions]]),0) -> 0.088019732 | Q10: =_xlfn.TEXTJOIN(", ", TRUE, Posts_Cleaned[[#This Row],[Hashtags Used.1]], Posts_Cleaned[[#This Row],[Hashtags Used.2]], Posts_Cleaned[[#This Row],[Hashtags Used.3]]) -> #TeslaCoInnovation | R10: =VLOOKUP(Posts_Cleaned[[#This Row],[Campaign_Name]],'Campaign Metadata Dataset '!$A$2:$B$5,2,0) -> 45566 | S10: =VLOOKUP(Posts_Cleaned[[#This Row],[Campaign_Name]],'Campaign Metadata Dataset '!$A$1:$C$5,3,0) -> 45596 | T10: =IF(AND(C10>R10, C10<=S10),"During Campaign","Before Campaign") -> Before Campaign | U10: =SUM(Posts_Cleaned[[#This Row],[Likes]]+Posts_Cleaned[[#This Row],[Shares]]+Posts_Cleaned[[#This Row],[Comments]]+Posts_Cleaned[[#This Row],[Clicks]]) -> 5127 | V10: =AVERAGEIF(Posts_Cleaned[[#This Row],[Period]]:T:T,"Before Campaign",Posts_Cleaned[[#This Row],[Engagement Rate ]]) -> 0.15343465 | W10: =AVERAGEIF($T$2:$T$302,"During Campaign",P10) -> 0.12142417 | X10: =(Posts_Cleaned[[#This Row],[During ]]-Posts_Cleaned[[#This Row],[Before ]])/Posts_Cleaned[[#This Row],[During ]] -> -0.26362521 | Y10: =IFERROR(VLOOKUP(O10, 'Campaign Metadata Dataset '!$A$1:$G$5,5,0),0) -> 200000 | Z10: =(F:F+G:G+H:H+K:K)/Y:Y -> 0.025635 | AA10: =(W:W-V:V)/W:W -> -0.26362521
A11: P010 | B11: Facebook | C11: 45727 | D11: Image | E11: Check out our latest image on facebook! | F11: 4241 | G11: 902 | H11: 47 | I11: 72097 | J11: 71598 | K11: 167 | L11: #TeslaCoInnovation | O11: ModelYCampaign | P11: =IFERROR(((Posts_Cleaned[[#This Row],[Likes]]+Posts_Cleaned[[#This Row],[Shares]]+Posts_Cleaned[[#This Row],[Comments]])/Posts_Cleaned[[#This Row],[Impressions]]),0) -> 0.071986352 | Q11: =_xlfn.TEXTJOIN(", ", TRUE, Posts_Cleaned[[#This Row],[Hashtags Used.1]], Posts_Cleaned[[#This Row],[Hashtags Used.2]], Posts_Cleaned[[#This Row],[Hashtags Used.3]]) -> #TeslaCoInnovation | R11: =VLOOKUP(Posts_Cleaned[[#This Row],[Campaign_Name]],'Campaign Metadata Dataset '!$A$2:$B$5,2,0) -> 45566 | S11: =VLOOKUP(Posts_Cleaned[[#This Row],[Campaign_Name]],'Campaign Metadata Dataset '!$A$1:$C$5,3,0) -> 45596 | T11: =IF(AND(C11>R11, C11<=S11),"During Campaign","Before Campaign") -> Before Campaign | U11: =SUM(Posts_Cleaned[[#This Row],[Likes]]+Posts_Cleaned[[#This Row],[Shares]]+Posts_Cleaned[[#This Row],[Comments]]+Posts_Cleaned[[#This Row],[Clicks]]) -> 5357 | V11: =AVERAGEIF(Posts_Cleaned[[#This Row],[Period]]:T:T,"Before Campaign",Posts_Cleaned[[#This Row],[Engagement Rate ]]) -> 0.15445597 | W11: =AVERAGEIF($T$2:$T$302,"During Campaign",P11) -> 0.1158695 | X11: =(Posts_Cleaned[[#This Row],[During ]]-Posts_Cleaned[[#This Row],[Before ]])/Posts_Cleaned[[#This Row],[During ]] -> -0.33301661 | Y11: =IFERROR(VLOOKUP(O11, 'Campaign Metadata Dataset '!$A$1:$G$5,5,0),0) -> 200000 | Z11: =(F:F+G:G+H:H+K:K)/Y:Y -> 0.026785 | AA11: =(W:W-V:V)/W:W -> -0.33301661
A12: P011 | B12: Instagram | C12: 45690 | D12: Story | E12: Check out our latest story on instagram! | F12: 1792 | G12: 614 | H12: 497 | I12: 25088 | J12: 24675 | K12: 65 | L12: #FutureOfDriving | O12: SustainabilityDrive | P12: =IFERROR(((Posts_Cleaned[[#This Row],[Likes]]+Posts_Cleaned[[#This Row],[Shares]]+Posts_Cleaned[[#This Row],[Comments]])/Posts_Cleaned[[#This Row],[Impressions]]),0) -> 0.11571269 | Q12: =_xlfn.TEXTJOIN(", ", TRUE, Posts_Cleaned[[#This Row],[Hashtags Used.1]], Posts_Cleaned[[#This Row],[Hashtags Used.2]], Posts_Cleaned[[#This Row],[Hashtags Used.3]]) -> #FutureOfDriving | R12: =VLOOKUP(Posts_Cleaned[[#This Row],[Campaign_Name]],'Campaign Metadata Dataset '!$A$2:$B$5,2,0) -> 45717 | S12: =VLOOKUP(Posts_Cleaned[[#This Row],[Campaign_Name]],'Campaign Metadata Dataset '!$A$1:$C$5,3,0) -> 45747 | T12: =IF(AND(C12>R12, C12<=S12),"During Campaign","Before Campaign") -> Before Campaign | U12: =SUM(Posts_Cleaned[[#This Row],[Likes]]+Posts_Cleaned[[#This Row],[Shares]]+Posts_Cleaned[[#This Row],[Comments]]+Posts_Cleaned[[#This Row],[Clicks]]) -> 2968 | V12: =AVERAGEIF(Posts_Cleaned[[#This Row],[Period]]:T:T,"Before Campaign",Posts_Cleaned[[#This Row],[Engagement Rate ]]) -> 0.14062878 | W12: =AVERAGEIF($T$2:$T$302,"During Campaign",P12) -> 0.12898688 | X12: =(Posts_Cleaned[[#This Row],[During ]]-Posts_Cleaned[[#This Row],[Before ]])/Posts_Cleaned[[#This Row],[During ]] -> -0.090256459 | Y12: =IFERROR(VLOOKUP(O12, 'Campaign Metadata Dataset '!$A$1:$G$5,5,0),0) -> 180000 | Z12: =(F:F+G:G+H:H+K:K)/Y:Y -> 0.016488889 | AA12: =(W:W-V:V)/W:W -> -0.090256459
A13: P012 | B13: Facebook | C13: 45494 | D13: Reel | E13: Check out our latest reel on facebook! | F13: 1946 | G13: 686 | H13: 377 | I13: 23352 | J13: 22982 | K13: 213 | L13: #FutureOfDriving | O13: FSDUpdate | P13: =IFERROR(((Posts_Cleaned[[#This Row],[Likes]]+Posts_Cleaned[[#This Row],[Shares]]+Posts_Cleaned[[#This Row],[Comments]])/Posts_Cleaned[[#This Row],[Impressions]]),0) -> 0.12885406 | Q13: =_xlfn.TEXTJOIN(", ", TRUE, Posts_Cleaned[[#This Row],[Hashtags Used.1]], Posts_Cleaned[[#This Row],[Hashtags Used.2]], Posts_Cleaned[[#This Row],[Hashtags Used.3]]) -> #FutureOfDriving | R13: =VLOOKUP(Posts_Cleaned[[#This Row],[Campaign_Name]],'Campaign Metadata Dataset '!$A$2:$B$5,2,0) -> 45651 | S13: =VLOOKUP(Posts_Cleaned[[#This Row],[Campaign_Name]],'Campaign Metadata Dataset '!$A$1:$C$5,3,0) -> 45667 | T13: =IF(AND(C13>R13, C13<=S13),"During Campaign","Before Campaign") -> Before Campaign | U13: =SUM(Posts_Cleaned[[#This Row],[Likes]]+Posts_Cleaned[[#This Row],[Shares]]+Posts_Cleaned[[#This Row],[Comments]]+Posts_Cleaned[[#This Row],[Clicks]]) -> 3222 | V13: =AVERAGEIF(Posts_Cleaned[[#This Row],[Period]]:T:T,"Before Campaign",Posts_Cleaned[[#This Row],[Engagement Rate ]]) -> 0.15123177 | W13: =AVERAGEIF($T$2:$T$302,"During Campaign",P13) -> 0.20263431 | X13: =(Posts_Cleaned[[#This Row],[During ]]-Posts_Cleaned[[#This Row],[Before ]])/Posts_Cleaned[[#This Row],[During ]] -> 0.25367142 | Y13: =IFERROR(VLOOKUP(O13, 'Campaign Metadata Dataset '!$A$1:$G$5,5,0),0) -> 250000 | Z13: =(F:F+G:G+H:H+K:K)/Y:Y -> 0.012888 | AA13: =(W:W-V:V)/W:W -> 0.25367142
A14: P013 | B14: YouTube | C14: 45614 | D14: Carousel | E14: Check out our latest carousel on youtube! | F14: 1171 | G14: 286 | H14: 231 | I14: 22249 | J14: 21282 | K14: 114 | L14: #EVRevolution | O14: CybertruckLaunch | P14: =IFERROR(((Posts_Cleaned[[#This Row],[Likes]]+Posts_Cleaned[[#This Row],[Shares]]+Posts_Cleaned[[#This Row],[Comments]])/Posts_Cleaned[[#This Row],[Impressions]]),0) -> 0.075868578 | Q14: =_xlfn.TEXTJOIN(", ", TRUE, Posts_Cleaned[[#This Row],[Hashtags Used.1]], Posts_Cleaned[[#This Row],[Hashtags Used.2]], Posts_Cleaned[[#This Row],[Hashtags Used.3]]) -> #EVRevolution | R14: =VLOOKUP(Posts_Cleaned[[#This Row],[Campaign_Name]],'Campaign Metadata Dataset '!$A$2:$B$5,2,0) -> 45458 | S14: =VLOOKUP(Posts_Cleaned[[#This Row],[Campaign_Name]],'Campaign Metadata Dataset '!$A$1:$C$5,3,0) -> 45488 | T14: =IF(AND(C14>R14, C14<=S14),"During Campaign","Before Campaign") -> Before Campaign | U14: =SUM(Posts_Cleaned[[#This Row],[Likes]]+Posts_Cleaned[[#This Row],[Shares]]+Posts_Cleaned[[#This Row],[Comments]]+Posts_Cleaned[[#This Row],[Clicks]]) -> 1802 | V14: =AVERAGEIF(Posts_Cleaned[[#This Row],[Period]]:T:T,"Before Campaign",Posts_Cleaned[[#This Row],[Engagement Rate ]]) -> 0.14104641 | W14: =AVERAGEIF($T$2:$T$302,"During Campaign",P14) -> 0.14487223 | X14: =(Posts_Cleaned[[#This Row],[During ]]-Posts_Cleaned[[#This Row],[Before ]])/Posts_Cleaned[[#This Row],[During ]] -> 0.026408272 | Y14: =IFERROR(VLOOKUP(O14, 'Campaign Metadata Dataset '!$A$1:$G$5,5,0),0) -> 150000 | Z14: =(F:F+G:G+H:H+K:K)/Y:Y -> 0.012013333 | AA14: =(W:W-V:V)/W:W -> 0.026408272
A15: P014 | B15: Facebook | C15: 45704 | D15: Story | E15: Check out our latest story on facebook! | F15: 4242 | G15: 555 | H15: 131 | I15: 33936 | J15: 33802 | K15: 265 | L15: #FutureOfDriving | P15: =IFERROR(((Posts_Cleaned[[#This Row],[Likes]]+Posts_Cleaned[[#This Row],[Shares]]+Posts_Cleaned[[#This Row],[Comments]])/Posts_Cleaned[[#This Row],[Impressions]]),0) -> 0.14521452 | Q15: =_xlfn.TEXTJOIN(", ", TRUE, Posts_Cleaned[[#This Row],[Hashtags Used.1]], Posts_Cleaned[[#This Row],[Hashtags Used.2]], Posts_Cleaned[[#This Row],[Hashtags Used.3]]) -> #FutureOfDriving | R15: =VLOOKUP(Posts_Cleaned[[#This Row],[Campaign_Name]],'Campaign Metadata Dataset '!$A$2:$B$5,2,0) -> #N/A | S15: =VLOOKUP(Posts_Cleaned[[#This Row],[Campaign_Name]],'Campaign Metadata Dataset '!$A$1:$C$5,3,0) -> #N/A | T15: =IF(AND(C15>R15, C15<=S15),"During Campaign","Before Campaign") -> #N/A | U15: =SUM(Posts_Cleaned[[#This Row],[Likes]]+Posts_Cleaned[[#This Row],[Shares]]+Posts_Cleaned[[#This Row],[Comments]]+Posts_Cleaned[[#This Row],[Clicks]]) -> 5193 | V15: =AVERAGEIF(Posts_Cleaned[[#This Row],[Period]]:T:T,"Before Campaign",Posts_Cleaned[[#This Row],[Engagement Rate ]]) -> 0.14054891 | W15: =AVERAGEIF($T$2:$T$302,"During Campaign",P15) -> 0.2165933 | X15: =(Posts_Cleaned[[#This Row],[During ]]-Posts_Cleaned[[#This Row],[Before ]])/Posts_Cleaned[[#This Row],[During ]] -> 0.35109297 | Y15: =IFERROR(VLOOKUP(O15, 'Campaign Metadata Dataset '!$A$1:$G$5,5,0),0) -> 0 | Z15: 0 | AA15: =(W:W-V:V)/W:W -> 0.35109297
A16: P015 | B16: Facebook | C16: 45589 | D16: Video | E16: Check out our latest video on facebook! | F16: 3888 | G16: 604 | H16: 128 | I16: 77760 | J16: 77167 | K16: 20 | L16: #FutureOfDriving | O16: CybertruckLaunch | P16: =IFERROR(((Posts_Cleaned[[#This Row],[Likes]]+Posts_Cleaned[[#This Row],[Shares]]+Posts_Cleaned[[#This Row],[Comments]])/Posts_Cleaned[[#This Row],[Impressions]]),0) -> 0.05941358 | Q16: =_xlfn.TEXTJOIN(", ", TRUE, Posts_Cleaned[[#This Row],[Hashtags Used.1]], Posts_Cleaned[[#This Row],[Hashtags Used.2]], Posts_Cleaned[[#This Row],[Hashtags Used.3]]) -> #FutureOfDriving | R16: =VLOOKUP(Posts_Cleaned[[#This Row],[Campaign_Name]],'Campaign Metadata Dataset '!$A$2:$B$5,2,0) -> 45458 | S16: =VLOOKUP(Posts_Cleaned[[#This Row],[Campaign_Name]],'Campaign Metadata Dataset '!$A$1:$C$5,3,0) -> 45488 | T16: =IF(AND(C16>R16, C16<=S16),"During Campaign","Before Campaign") -> Before Campaign | U16: =SUM(Posts_Cleaned[[#This Row],[Likes]]+Posts_Cleaned[[#This Row],[Shares]]+Posts_Cleaned[[#This Row],[Comments]]+Posts_Cleaned[[#This Row],[Clicks]]) -> 4640 | V16: =AVERAGEIF(Posts_Cleaned[[#This Row],[Period]]:T:T,"Before Campaign",Posts_Cleaned[[#This Row],[Engagement Rate ]]) -> 0.14759713 | W16: =AVERAGEIF($T$2:$T$302,"During Campaign",P16) -> 0.20701069 | X16: =(Posts_Cleaned[[#This Row],[During ]]-Posts_Cleaned[[#This Row],[Before ]])/Posts_Cleaned[[#This Row],[During ]] -> 0.2870072 | Y16: =IFERROR(VLOOKUP(O16, 'Campaign Metadata Dataset '!$A$1:$G$5,5,0),0) -> 150000 | Z16: =(F:F+G:G+H:H+K:K)/Y:Y -> 0.030933333 | AA16: =(W:W-V:V)/W:W -> 0.2870072
A17: P016 | B17: Facebook | C17: 45530 | D17: Text | E17: Check out our latest text on facebook! | F17: 3452 | G17: 377 | H17: 360 | I17: 55232 | J17: 55075 | K17: 87 | L17: #FutureOfDriving | O17: FSDUpdate | P17: =IFERROR(((Posts_Cleaned[[#This Row],[Likes]]+Posts_Cleaned[[#This Row],[Shares]]+Posts_Cleaned[[#This Row],[Comments]])/Posts_Cleaned[[#This Row],[Impressions]]),0) -> 0.075843714 | Q17: =_xlfn.TEXTJOIN(", ", TRUE, Posts_Cleaned[[#This Row],[Hashtags Used.1]], Posts_Cleaned[[#This Row],[Hashtags Used.2]], Posts_Cleaned[[#This Row],[Hashtags Used.3]]) -> #FutureOfDriving | R17: =VLOOKUP(Posts_Cleaned[[#This Row],[Campaign_Name]],'Campaign Metadata Dataset '!$A$2:$B$5,2,0) -> 45651 | S17: =VLOOKUP(Posts_Cleaned[[#This Row],[Campaign_Name]],'Campaign Metadata Dataset '!$A$1:$C$5,3,0) -> 45667 | T17: =IF(AND(C17>R17, C17<=S17),"During Campaign","Before Campaign") -> Before Campaign | U17: =SUM(Posts_Cleaned[[#This Row],[Likes]]+Posts_Cleaned[[#This Row],[Shares]]+Posts_Cleaned[[#This Row],[Comments]]+Posts_Cleaned[[#This Row],[Clicks]]) -> 4276 | V17: =AVERAGEIF(Posts_Cleaned[[#This Row],[Period]]:T:T,"Before Campaign",Posts_Cleaned[[#This Row],[Engagement Rate ]]) -> 0.14369206 | W17: =AVERAGEIF($T$2:$T$302,"During Campaign",P17) -> 0.14575989 | X17: =(Posts_Cleaned[[#This Row],[During ]]-Posts_Cleaned[[#This Row],[Before ]])/Posts_Cleaned[[#This Row],[During ]] -> 0.014186563 | Y17: =IFERROR(VLOOKUP(O17, 'Campaign Metadata Dataset '!$A$1:$G$5,5,0),0) -> 250000 | Z17: =(F:F+G:G+H:H+K:K)/Y:Y -> 0.017104 | AA17: =(W:W-V:V)/W:W -> 0.014186563
A18: P017 | B18: Facebook | C18: 45782 | D18: Text | E18: Check out our latest text on facebook! | F18: 4441 | G18: 511 | H18: 70 | I18: 53292 | J18: 53082 | K18: 159 | L18: #EVRevolution | O18: SustainabilityDrive | P18: =IFERROR(((Posts_Cleaned[[#This Row],[Likes]]+Posts_Cleaned[[#This Row],[Shares]]+Posts_Cleaned[[#This Row],[Comments]])/Posts_Cleaned[[#This Row],[Impressions]]),0) -> 0.094235533 | Q18: =_xlfn.TEXTJOIN(", ", TRUE, Posts_Cleaned[[#This Row],[Hashtags Used.1]], Posts_Cleaned[[#This Row],[Hashtags Used.2]], Posts_Cleaned[[#This Row],[Hashtags Used.3]]) -> #EVRevolution | R18: =VLOOKUP(Posts_Cleaned[[#This Row],[Campaign_Name]],'Campaign Metadata Dataset '!$A$2:$B$5,2,0) -> 45717 | S18: =VLOOKUP(Posts_Cleaned[[#This Row],[Campaign_Name]],'Campaign Metadata Dataset '!$A$1:$C$5,3,0) -> 45747 | T18: =IF(AND(C18>R18, C18<=S18),"During Campaign","Before Campaign") -> Before Campaign | U18: =SUM(Posts_Cleaned[[#This Row],[Likes]]+Posts_Cleaned[[#This Row],[Shares]]+Posts_Cleaned[[#This Row],[Comments]]+Posts_Cleaned[[#This Row],[Clicks]]) -> 5181 | V18: =AVERAGEIF(Posts_Cleaned[[#This Row],[Period]]:T:T,"Before Campaign",Posts_Cleaned[[#This Row],[Engagement Rate ]]) -> 0.14927162 | W18: =AVERAGEIF($T$2:$T$302,"During Campaign",P18) -> 0.20432316 | X18: =(Posts_Cleaned[[#This Row],[During ]]-Posts_Cleaned[[#This Row],[Before ]])/Posts_Cleaned[[#This Row],[During ]] -> 0.26943369 | Y18: =IFERROR(VLOOKUP(O18, 'Campaign Metadata Dataset '!$A$1:$G$5,5,0),0) -> 180000 | Z18: =(F:F+G:G+H:H+K:K)/Y:Y -> 0.028783333 | AA18: =(W:W-V:V)/W:W -> 0.26943369
A19: P018 | B19: Instagram | C19: 45523 | D19: Reel | E19: Check out our latest reel on instagram! | F19: 3000 | G19: 382 | H19: 325 | I19: 36000 | J19: 35819 | K19: 19 | L19: #FutureOfDriving | O19: CybertruckLaunch | P19: =IFERROR(((Posts_Cleaned[[#This Row],[Likes]]+Posts_Cleaned[[#This Row],[Shares]]+Posts_Cleaned[[#This Row],[Comments]])/Posts_Cleaned[[#This Row],[Impressions]]),0) -> 0.10297222 | Q19: =_xlfn.TEXTJOIN(", ", TRUE, Posts_Cleaned[[#This Row],[Hashtags Used.1]], Posts_Cleaned[[#This Row],[Hashtags Used.2]], Posts_Cleaned[[#This Row],[Hashtags Used.3]]) -> #FutureOfDriving | R19: =VLOOKUP(Posts_Cleaned[[#This Row],[Campaign_Name]],'Campaign Metadata Dataset '!$A$2:$B$5,2,0) -> 45458 | S19: =VLOOKUP(Posts_Cleaned[[#This Row],[Campaign_Name]],'Campaign Metadata Dataset '!$A$1:$C$5,3,0) -> 45488 | T19: =IF(AND(C19>R19, C19<=S19),"During Campaign","Before Campaign") -> Before Campaign | U19: =SUM(Posts_Cleaned[[#This Row],[Likes]]+Posts_Cleaned[[#This Row],[Shares]]+Posts_Cleaned[[#This Row],[Comments]]+Posts_Cleaned[[#This Row],[Clicks]]) -> 3726 | V19: =AVERAGEIF(Posts_Cleaned[[#This Row],[Period]]:T:T,"Before Campaign",Posts_Cleaned[[#This Row],[Engagement Rate ]]) -> 0.14617288 | W19: =AVERAGEIF($T$2:$T$302,"During Campaign",P19) -> 0.16177417 | X19: =(Posts_Cleaned[[#This Row],[During ]]-Posts_Cleaned[[#This Row],[Before ]])/Posts_Cleaned[[#This Row],[During ]] -> 0.096438693 | Y19: =IFERROR(VLOOKUP(O19, 'Campaign Metadata Dataset '!$A$1:$G$5,5,0),0) -> 150000 | Z19: =(F:F+G:G+H:H+K:K)/Y:Y -> 0.02484 | AA19: =(W:W-V:V)/W:W -> 0.096438693
A20: P019 | B20: Instagram | C20: 45466 | D20: Video | E20: Check out our latest video on instagram! | F20: 1071 | G20: 519 | H20: 22 | I20: 16065 | J20: 15865 | K20: 103 | L20: #TeslaCoInnovation | O20: SustainabilityDrive | P20: =IFERROR(((Posts_Cleaned[[#This Row],[Likes]]+Posts_Cleaned[[#This Row],[Shares]]+Posts_Cleaned[[#This Row],[Comments]])/Posts_Cleaned[[#This Row],[Impressions]]),0) -> 0.10034236 | Q20: =_xlfn.TEXTJOIN(", ", TRUE, Posts_Cleaned[[#This Row],[Hashtags Used.1]], Posts_Cleaned[[#This Row],[Hashtags Used.2]], Posts_Cleaned[[#This Row],[Hashtags Used.3]]) -> #TeslaCoInnovation | R20: =VLOOKUP(Posts_Cleaned[[#This Row],[Campaign_Name]],'Campaign Metadata Dataset '!$A$2:$B$5,2,0) -> 45717 | S20: =VLOOKUP(Posts_Cleaned[[#This Row],[Campaign_Name]],'Campaign Metadata Dataset '!$A$1:$C$5,3,0) -> 45747 | T20: =IF(AND(C20>R20, C20<=S20),"During Campaign","Before Campaign") -> Before Campaign | U20: =SUM(Posts_Cleaned[[#This Row],[Likes]]+Posts_Cleaned[[#This Row],[Shares]]+Posts_Cleaned[[#This Row],[Comments]]+Posts_Cleaned[[#This Row],[Clicks]]) -> 1715 | V20: =AVERAGEIF(Posts_Cleaned[[#This Row],[Period]]:T:T,"Before Campaign",Posts_Cleaned[[#This Row],[Engagement Rate ]]) -> 0.14979441 | W20: =AVERAGEIF($T$2:$T$302,"During Campaign",P20) -> 0.1737095 | X20: =(Posts_Cleaned[[#This Row],[During ]]-Posts_Cleaned[[#This Row],[Before ]])/Posts_Cleaned[[#This Row],[During ]] -> 0.13767289 | Y20: =IFERROR(VLOOKUP(O20, 'Campaign Metadata Dataset '!$A$1:$G$5,5,0),0) -> 180000 | Z20: =(F:F+G:G+H:H+K:K)/Y:Y -> 0.0095277778 | AA20: =(W:W-V:V)/W:W -> 0.13767289
A21: P020 | B21: Instagram | C21: 45544 | D21: Carousel | E21: Check out our latest carousel on instagram! | F21: 4054 | G21: 488 | H21: 373 | I21: 77026 | J21: 76881 | K21: 25 | L21: #TeslaCoInnovation | O21: CybertruckLaunch | P21: =IFERROR(((Posts_Cleaned[[#This Row],[Likes]]+Posts_Cleaned[[#This Row],[Shares]]+Posts_Cleaned[[#This Row],[Comments]])/Posts_Cleaned[[#This Row],[Impressions]]),0) -> 0.063809623 | Q21: =_xlfn.TEXTJOIN(", ", TRUE, Posts_Cleaned[[#This Row],[Hashtags Used.1]], Posts_Cleaned[[#This Row],[Hashtags Used.2]], Posts_Cleaned[[#This Row],[Hashtags Used.3]]) -> #TeslaCoInnovation | R21: =VLOOKUP(Posts_Cleaned[[#This Row],[Campaign_Name]],'Campaign Metadata Dataset '!$A$2:$B$5,2,0) -> 45458 | S21: =VLOOKUP(Posts_Cleaned[[#This Row],[Campaign_Name]],'Campaign Metadata Dataset '!$A$1:$C$5,3,0) -> 45488 | T21: =IF(AND(C21>R21, C21<=S21),"During Campaign","Before Campaign") -> Before Campaign | U21: =SUM(Posts_Cleaned[[#This Row],[Likes]]+Posts_Cleaned[[#This Row],[Shares]]+Posts_Cleaned[[#This Row],[Comments]]+Posts_Cleaned[[#This Row],[Clicks]]) -> 4940 | V21: =AVERAGEIF(Posts_Cleaned[[#This Row],[Period]]:T:T,"Before Campaign",Posts_Cleaned[[#This Row],[Engagement Rate ]]) -> 0.15667334 | W21: =AVERAGEIF($T$2:$T$302,"During Campaign",P21) -> 0.14948499 | X21: =(Posts_Cleaned[[#This Row],[During ]]-Posts_Cleaned[[#This Row],[Before ]])/Posts_Cleaned[[#This Row],[During ]] -> -0.048087418 | Y21: =IFERROR(VLOOKUP(O21, 'Campaign Metadata Dataset '!$A$1:$G$5,5,0),0) -> 150000 | Z21: =(F:F+G:G+H:H+K:K)/Y:Y -> 0.032933333 | AA21: =(W:W-V:V)/W:W -> -0.048087418
A22: P021 | B22: Instagram | C22: 45661 | D22: Reel | E22: Check out our latest reel on instagram! | F22: 4838 | G22: 640 | H22: 128 | I22: 72570 | J22: 72396 | K22: 83 | L22: #FutureOfDriving | O22: SustainabilityDrive | P22: =IFERROR(((Posts_Cleaned[[#This Row],[Likes]]+Posts_Cleaned[[#This Row],[Shares]]+Posts_Cleaned[[#This Row],[Comments]])/Posts_Cleaned[[#This Row],[Impressions]]),0) -> 0.077249552 | Q22: =_xlfn.TEXTJOIN(", ", TRUE, Posts_Cleaned[[#This Row],[Hashtags Used.1]], Posts_Cleaned[[#This Row],[Hashtags Used.2]], Posts_Cleaned[[#This Row],[Hashtags Used.3]]) -> #FutureOfDriving | R22: =VLOOKUP(Posts_Cleaned[[#This Row],[Campaign_Name]],'Campaign Metadata Dataset '!$A$2:$B$5,2,0) -> 45717 | S22: =VLOOKUP(Posts_Cleaned[[#This Row],[Campaign_Name]],'Campaign Metadata Dataset '!$A$1:$C$5,3,0) -> 45747 | T22: =IF(AND(C22>R22, C22<=S22),"During Campaign","Before Campaign") -> Before Campaign | U22: =SUM(Posts_Cleaned[[#This Row],[Likes]]+Posts_Cleaned[[#This Row],[Shares]]+Posts_Cleaned[[#This Row],[Comments]]+Posts_Cleaned[[#This Row],[Clicks]]) -> 5689 | V22: =AVERAGEIF(Posts_Cleaned[[#This Row],[Period]]:T:T,"Before Campaign",Posts_Cleaned[[#This Row],[Engagement Rate ]]) -> 0.15641971 | W22: =AVERAGEIF($T$2:$T$302,"During Campaign",P22) -> 0.13014816 | X22: =(Posts_Cleaned[[#This Row],[During ]]-Posts_Cleaned[[#This Row],[Before ]])/Posts_Cleaned[[#This Row],[During ]] -> -0.20185879 | Y22: =IFERROR(VLOOKUP(O22, 'Campaign Metadata Dataset '!$A$1:$G$5,5,0),0) -> 180000 | Z22: =(F:F+G:G+H:H+K:K)/Y:Y -> 0.031605556 | AA22: =(W:W-V:V)/W:W -> -0.20185879
A23: P022 | B23: Facebook | C23: 45715 | D23: Text | E23: Check out our latest text on facebook! | F23: 1570 | G23: 187 | H23: 260 | I23: 25120 | J23: 24613 | K23: 133 | L23: #TeslaCoInnovation | O23: SustainabilityDrive | P23: =IFERROR(((Posts_Cleaned[[#This Row],[Likes]]+Posts_Cleaned[[#This Row],[Shares]]+Posts_Cleaned[[#This Row],[Comments]])/Posts_Cleaned[[#This Row],[Impressions]]),0) -> 0.080294586 | Q23: =_xlfn.TEXTJOIN(", ", TRUE, Posts_Cleaned[[#This Row],[Hashtags Used.1]], Posts_Cleaned[[#This Row],[Hashtags Used.2]], Posts_Cleaned[[#This Row],[Hashtags Used.3]]) -> #TeslaCoInnovation | R23: =VLOOKUP(Posts_Cleaned[[#This Row],[Campaign_Name]],'Campaign Metadata Dataset '!$A$2:$B$5,2,0) -> 45717 | S23: =VLOOKUP(Posts_Cleaned[[#This Row],[Campaign_Name]],'Campaign Metadata Dataset '!$A$1:$C$5,3,0) -> 45747 | T23: =IF(AND(C23>R23, C23<=S23),"During Campaign","Before Campaign") -> Before Campaign | U23: =SUM(Posts_Cleaned[[#This Row],[Likes]]+Posts_Cleaned[[#This Row],[Shares]]+Posts_Cleaned[[#This Row],[Comments]]+Posts_Cleaned[[#This Row],[Clicks]]) -> 2150 | V23: =AVERAGEIF(Posts_Cleaned[[#This Row],[Period]]:T:T,"Before Campaign",Posts_Cleaned[[#This Row],[Engagement Rate ]]) -> 0.14740344 | W23: =AVERAGEIF($T$2:$T$302,"During Campaign",P23) -> 0.15893105 | X23: =(Posts_Cleaned[[#This Row],[During ]]-Posts_Cleaned[[#This Row],[Before ]])/Posts_Cleaned[[#This Row],[During ]] -> 0.07253213 | Y23: =IFERROR(VLOOKUP(O23, 'Campaign Metadata Dataset '!$A$1:$G$5,5,0),0) -> 180000 | Z23: =(F:F+G:G+H:H+K:K)/Y:Y -> 0.011944444 | AA23: =(W:W-V:V)/W:W -> 0.07253213
A24: P023 | B24: Facebook | C24: 45602 | D24: Video | E24: Check out our latest video on facebook! | F24: 1606 | G24: 547 | H24: 316 | I24: 32120 | J24: 31736 | K24: 225 | L24: #TeslaCoInnovation | M24: #AnytimeIsTeslaTime | O24: ModelYCampaign | P24: =IFERROR(((Posts_Cleaned[[#This Row],[Likes]]+Posts_Cleaned[[#This Row],[Shares]]+Posts_Cleaned[[#This Row],[Comments]])/Posts_Cleaned[[#This Row],[Impressions]]),0) -> 0.076867995 | Q24: =_xlfn.TEXTJOIN(", ", TRUE, Posts_Cleaned[[#This Row],[Hashtags Used.1]], Posts_Cleaned[[#This Row],[Hashtags Used.2]], Posts_Cleaned[[#This Row],[Hashtags Used.3]]) -> #TeslaCoInnovation, #AnytimeIsTeslaTime | R24: =VLOOKUP(Posts_Cleaned[[#This Row],[Campaign_Name]],'Campaign Metadata Dataset '!$A$2:$B$5,2,0) -> 45566 | S24: =VLOOKUP(Posts_Cleaned[[#This Row],[Campaign_Name]],'Campaign Metadata Dataset '!$A$1:$C$5,3,0) -> 45596 | T24: =IF(AND(C24>R24, C24<=S24),"During Campaign","Before Campaign") -> Before Campaign | U24: =SUM(Posts_Cleaned[[#This Row],[Likes]]+Posts_Cleaned[[#This Row],[Shares]]+Posts_Cleaned[[#This Row],[Comments]]+Posts_Cleaned[[#This Row],[Clicks]]) -> 2694 | V24: =AVERAGEIF(Posts_Cleaned[[#This Row],[Period]]:T:T,"Before Campaign",Posts_Cleaned[[#This Row],[Engagement Rate ]]) -> 0.15478526 | W24: =AVERAGEIF($T$2:$T$302,"During Campaign",P24) -> 0.18960705 | X24: =(Posts_Cleaned[[#This Row],[During ]]-Posts_Cleaned[[#This Row],[Before ]])/Posts_Cleaned[[#This Row],[During ]] -> 0.18365243 | Y24: =IFERROR(VLOOKUP(O24, 'Campaign Metadata Dataset '!$A$1:$G$5,5,0),0) -> 200000 | Z24: =(F:F+G:G+H:H+K:K)/Y:Y -> 0.01347 | AA24: =(W:W-V:V)/W:W -> 0.18365243
A25: P024 | B25: Facebook | C25: 45680 | D25: Video | E25: Check out our latest video on facebook! | F25: 3961 | G25: 761 | H25: 131 | I25: 67337 | J25: 66615 | K25: 161 | L25: #FutureOfDriving | O25: FSDUpdate | P25: =IFERROR(((Posts_Cleaned[[#This Row],[Likes]]+Posts_Cleaned[[#This Row],[Shares]]+Posts_Cleaned[[#This Row],[Comments]])/Posts_Cleaned[[#This Row],[Impressions]]),0) -> 0.072070333 | Q25: =_xlfn.TEXTJOIN(", ", TRUE, Posts_Cleaned[[#This Row],[Hashtags Used.1]], Posts_Cleaned[[#This Row],[Hashtags Used.2]], Posts_Cleaned[[#This Row],[Hashtags Used.3]]) -> #FutureOfDriving | R25: =VLOOKUP(Posts_Cleaned[[#This Row],[Campaign_Name]],'Campaign Metadata Dataset '!$A$2:$B$5,2,0) -> 45651 | S25: =VLOOKUP(Posts_Cleaned[[#This Row],[Campaign_Name]],'Campaign Metadata Dataset '!$A$1:$C$5,3,0) -> 45667 | T25: =IF(AND(C25>R25, C25<=S25),"During Campaign","Before Campaign") -> Before Campaign | U25: =SUM(Posts_Cleaned[[#This Row],[Likes]]+Posts_Cleaned[[#This Row],[Shares]]+Posts_Cleaned[[#This Row],[Comments]]+Posts_Cleaned[[#This Row],[Clicks]]) -> 5014 | V25: =AVERAGEIF(Posts_Cleaned[[#This Row],[Period]]:T:T,"Before Campaign",Posts_Cleaned[[#This Row],[Engagement Rate ]]) -> 0.15728692 | W25: =AVERAGEIF($T$2:$T$302,"During Campaign",P25) -> 0.14645307 | X25: =(Posts_Cleaned[[#This Row],[During ]]-Posts_Cleaned[[#This Row],[Before ]])/Posts_Cleaned[[#This Row],[During ]] -> -0.073974897 | Y25: =IFERROR(VLOOKUP(O25, 'Campaign Metadata Dataset '!$A$1:$G$5,5,0),0) -> 250000 | Z25: =(F:F+G:G+H:H+K:K)/Y:Y -> 0.020056 | AA25: =(W:W-V:V)/W:W -> -0.073974897
A26: P025 | B26: X | C26: 45757 | D26: Carousel | E26: Check out our latest carousel on twitter! | F26: 3128 | G26: 211 | H26: 197 | I26: 59432 | J26: 59182 | K26: 238 | L26: #EVRevolution | P26: =IFERROR(((Posts_Cleaned[[#This Row],[Likes]]+Posts_Cleaned[[#This Row],[Shares]]+Posts_Cleaned[[#This Row],[Comments]])/Posts_Cleaned[[#This Row],[Impressions]]),0) -> 0.059496568 | Q26: =_xlfn.TEXTJOIN(", ", TRUE, Posts_Cleaned[[#This Row],[Hashtags Used.1]], Posts_Cleaned[[#This Row],[Hashtags Used.2]], Posts_Cleaned[[#This Row],[Hashtags Used.3]]) -> #EVRevolution | R26: =VLOOKUP(Posts_Cleaned[[#This Row],[Campaign_Name]],'Campaign Metadata Dataset '!$A$2:$B$5,2,0) -> #N/A | S26: =VLOOKUP(Posts_Cleaned[[#This Row],[Campaign_Name]],'Campaign Metadata Dataset '!$A$1:$C$5,3,0) -> #N/A | T26: =IF(AND(C26>R26, C26<=S26),"During Campaign","Before Campaign") -> #N/A | U26: =SUM(Posts_Cleaned[[#This Row],[Likes]]+Posts_Cleaned[[#This Row],[Shares]]+Posts_Cleaned[[#This Row],[Comments]]+Posts_Cleaned[[#This Row],[Clicks]]) -> 3774 | V26: =AVERAGEIF(Posts_Cleaned[[#This Row],[Period]]:T:T,"Before Campaign",Posts_Cleaned[[#This Row],[Engagement Rate ]]) -> 0.14598198 | W26: =AVERAGEIF($T$2:$T$302,"During Campaign",P26) -> 0.10815794 | X26: =(Posts_Cleaned[[#This Row],[During ]]-Posts_Cleaned[[#This Row],[Before ]])/Posts_Cleaned[[#This Row],[During ]] -> -0.34971118 | Y26: =IFERROR(VLOOKUP(O26, 'Campaign Metadata Dataset '!$A$1:$G$5,5,0),0) -> 0 | Z26: 0 | AA26: =(W:W-V:V)/W:W -> -0.34971118
A27: P026 | B27: YouTube | C27: 45752 | D27: Reel | E27: Check out our latest reel on youtube! | F27: 3009 | G27: 413 | H27: 358 | I27: 42126 | J27: 41309 | K27: 211 | L27: #FutureOfDriving | O27: ModelYCampaign | P27: =IFERROR(((Posts_Cleaned[[#This Row],[Likes]]+Posts_Cleaned[[#This Row],[Shares]]+Posts_Cleaned[[#This Row],[Comments]])/Posts_Cleaned[[#This Row],[Impressions]]),0) -> 0.089730808 | Q27: =_xlfn.TEXTJOIN(", ", TRUE, Posts_Cleaned[[#This Row],[Hashtags Used.1]], Posts_Cleaned[[#This Row],[Hashtags Used.2]], Posts_Cleaned[[#This Row],[Hashtags Used.3]]) -> #FutureOfDriving | R27: =VLOOKUP(Posts_Cleaned[[#This Row],[Campaign_Name]],'Campaign Metadata Dataset '!$A$2:$B$5,2,0) -> 45566 | S27: =VLOOKUP(Posts_Cleaned[[#This Row],[Campaign_Name]],'Campaign Metadata Dataset '!$A$1:$C$5,3,0) -> 45596 | T27: =IF(AND(C27>R27, C27<=S27),"During Campaign","Before Campaign") -> Before Campaign | U27: =SUM(Posts_Cleaned[[#This Row],[Likes]]+Posts_Cleaned[[#This Row],[Shares]]+Posts_Cleaned[[#This Row],[Comments]]+Posts_Cleaned[[#This Row],[Clicks]]) -> 3991 | V27: =AVERAGEIF(Posts_Cleaned[[#This Row],[Period]]:T:T,"Before Campaign",Posts_Cleaned[[#This Row],[Engagement Rate ]]) -> 0.15417875 | W27: =AVERAGEIF($T$2:$T$302,"During Campaign",P27) -> 0.19877262 | X27: =(Posts_Cleaned[[#This Row],[During ]]-Posts_Cleaned[[#This Row],[Before ]])/Posts_Cleaned[[#This Row],[During ]] -> 0.22434611 | Y27: =IFERROR(VLOOKUP(O27, 'Campaign Metadata Dataset '!$A$1:$G$5,5,0),0) -> 200000 | Z27: =(F:F+G:G+H:H+K:K)/Y:Y -> 0.019955 | AA27: =(W:W-V:V)/W:W -> 0.22434611
A28: P027 | B28: YouTube | C28: 45552 | D28: Text | E28: Check out our latest text on youtube! | F28: 2076 | G28: 195 | H28: 104 | I28: 33216 | J28: 32244 | K28: 51 | L28: #FutureOfDriving | O28: SustainabilityDrive | P28: =IFERROR(((Posts_Cleaned[[#This Row],[Likes]]+Posts_Cleaned[[#This Row],[Shares]]+Posts_Cleaned[[#This Row],[Comments]])/Posts_Cleaned[[#This Row],[Impressions]]),0) -> 0.071501686 | Q28: =_xlfn.TEXTJOIN(", ", TRUE, Posts_Cleaned[[#This Row],[Hashtags Used.1]], Posts_Cleaned[[#This Row],[Hashtags Used.2]], Posts_Cleaned[[#This Row],[Hashtags Used.3]]) -> #FutureOfDriving | R28: =VLOOKUP(Posts_Cleaned[[#This Row],[Campaign_Name]],'Campaign Metadata Dataset '!$A$2:$B$5,2,0) -> 45717 | S28: =VLOOKUP(Posts_Cleaned[[#This Row],[Campaign_Name]],'Campaign Metadata Dataset '!$A$1:$C$5,3,0) -> 45747 | T28: =IF(AND(C28>R28, C28<=S28),"During Campaign","Before Campaign") -> Before Campaign | U28: =SUM(Posts_Cleaned[[#This Row],[Likes]]+Posts_Cleaned[[#This Row],[Shares]]+Posts_Cleaned[[#This Row],[Comments]]+Posts_Cleaned[[#This Row],[Clicks]]) -> 2426 | V28: =AVERAGEIF(Posts_Cleaned[[#This Row],[Period]]:T:T,"Before Campaign",Posts_Cleaned[[#This Row],[Engagement Rate ]]) -> 0.16356515 | W28: =AVERAGEIF($T$2:$T$302,"During Campaign",P28) -> 0.19829823 | X28: =(Posts_Cleaned[[#This Row],[During ]]-Posts_Cleaned[[#This Row],[Before ]])/Posts_Cleaned[[#This Row],[During ]] -> 0.17515581 | Y28: =IFERROR(VLOOKUP(O28, 'Campaign Metadata Dataset '!$A$1:$G$5,5,0),0) -> 180000 | Z28: =(F:F+G:G+H:H+K:K)/Y:Y -> 0.013477778 | AA28: =(W:W-V:V)/W:W -> 0.17515581
A29: P028 | B29: Instagram | C29: 45720 | D29: Video | E29: Check out our latest video on instagram! | F29: 432 | G29: 624 | H29: 123 | I29: 6912 | J29: 6259 | K29: 79 | L29: #FutureOfDriving | O29: SustainabilityDrive | P29: =IFERROR(((Posts_Cleaned[[#This Row],[Likes]]+Posts_Cleaned[[#This Row],[Shares]]+Posts_Cleaned[[#This Row],[Comments]])/Posts_Cleaned[[#This Row],[Impressions]]),0) -> 0.17057292 | Q29: =_xlfn.TEXTJOIN(", ", TRUE, Posts_Cleaned[[#This Row],[Hashtags Used.1]], Posts_Cleaned[[#This Row],[Hashtags Used.2]], Posts_Cleaned[[#This Row],[Hashtags Used.3]]) -> #FutureOfDriving | R29: =VLOOKUP(Posts_Cleaned[[#This Row],[Campaign_Name]],'Campaign Metadata Dataset '!$A$2:$B$5,2,0) -> 45717 | S29: =VLOOKUP(Posts_Cleaned[[#This Row],[Campaign_Name]],'Campaign Metadata Dataset '!$A$1:$C$5,3,0) -> 45747 | T29: =IF(AND(C29>R29, C29<=S29),"During Campaign","Before Campaign") -> During Campaign | U29: =SUM(Posts_Cleaned[[#This Row],[Likes]]+Posts_Cleaned[[#This Row],[Shares]]+Posts_Cleaned[[#This Row],[Comments]]+Posts_Cleaned[[#This Row],[Clicks]]) -> 1258 | V29: =AVERAGEIF(Posts_Cleaned[[#This Row],[Period]]:T:T,"Before Campaign",Posts_Cleaned[[#This Row],[Engagement Rate ]]) -> 0.14237469 | W29: =AVERAGEIF($T$2:$T$302,"During Campaign",P29) -> 0.10684433 | X29: =(Posts_Cleaned[[#This Row],[During ]]-Posts_Cleaned[[#This Row],[Before ]])/Posts_Cleaned[[#This Row],[During ]] -> -0.33254328 | Y29: =IFERROR(VLOOKUP(O29, 'Campaign Metadata Dataset '!$A$1:$G$5,5,0),0) -> 180000 | Z29: =(F:F+G:G+H:H+K:K)/Y:Y -> 0.0069888889 | AA29: =(W:W-V:V)/W:W -> -0.33254328
A30: P029 | B30: Instagram | C30: 45688 | D30: Carousel | E30: Check out our latest carousel on instagram! | F30: 2566 | G30: 118 | H30: 37 | I30: 12830 | J30: 12264 | K30: 221 | L30: #FutureOfDriving | O30: FSDUpdate | P30: =IFERROR(((Posts_Cleaned[[#This Row],[Likes]]+Posts_Cleaned[[#This Row],[Shares]]+Posts_Cleaned[[#This Row],[Comments]])/Posts_Cleaned[[#This Row],[Impressions]]),0) -> 0.21208106 | Q30: =_xlfn.TEXTJOIN(", ", TRUE, Posts_Cleaned[[#This Row],[Hashtags Used.1]], Posts_Cleaned[[#This Row],[Hashtags Used.2]], Posts_Cleaned[[#This Row],[Hashtags Used.3]]) -> #FutureOfDriving | R30: =VLOOKUP(Posts_Cleaned[[#This Row],[Campaign_Name]],'Campaign Metadata Dataset '!$A$2:$B$5,2,0) -> 45651 | S30: =VLOOKUP(Posts_Cleaned[[#This Row],[Campaign_Name]],'Campaign Metadata Dataset '!$A$1:$C$5,3,0) -> 45667 | T30: =IF(AND(C30>R30, C30<=S30),"During Campaign","Before Campaign") -> Before Campaign | U30: =SUM(Posts_Cleaned[[#This Row],[Likes]]+Posts_Cleaned[[#This Row],[Shares]]+Posts_Cleaned[[#This Row],[Comments]]+Posts_Cleaned[[#This Row],[Clicks]]) -> 2942 | V30: =AVERAGEIF(Posts_Cleaned[[#This Row],[Period]]:T:T,"Before Campaign",Posts_Cleaned[[#This Row],[Engagement Rate ]]) -> 0.15621542 | W30: =AVERAGEIF($T$2:$T$302,"During Campaign",P30) -> 0.17789449 | X30: =(Posts_Cleaned[[#This Row],[During ]]-Posts_Cleaned[[#This Row],[Before ]])/Posts_Cleaned[[#This Row],[During ]] -> 0.1218648 | Y30: =IFERROR(VLOOKUP(O30, 'Campaign Metadata Dataset '!$A$1:$G$5,5,0),0) -> 250000 | Z30: =(F:F+G:G+H:H+K:K)/Y:Y -> 0.011768 | AA30: =(W:W-V:V)/W:W -> 0.1218648
A31: P030 | B31: Instagram | C31: 45713 | D31: Video | E31: Check out our latest video on instagram! | F31: 3095 | G31: 39 | H31: 78 | I31: 55710 | J31: 54808 | K31: 93 | L31: #EVRevolution | P31: =IFERROR(((Posts_Cleaned[[#This Row],[Likes]]+Posts_Cleaned[[#This Row],[Shares]]+Posts_Cleaned[[#This Row],[Comments]])/Posts_Cleaned[[#This Row],[Impressions]]),0) -> 0.057655717 | Q31: =_xlfn.TEXTJOIN(", ", TRUE, Posts_Cleaned[[#This Row],[Hashtags Used.1]], Posts_Cleaned[[#This Row],[Hashtags Used.2]], Posts_Cleaned[[#This Row],[Hashtags Used.3]]) -> #EVRevolution | R31: =VLOOKUP(Posts_Cleaned[[#This Row],[Campaign_Name]],'Campaign Metadata Dataset '!$A$2:$B$5,2,0) -> #N/A | S31: =VLOOKUP(Posts_Cleaned[[#This Row],[Campaign_Name]],'Campaign Metadata Dataset '!$A$1:$C$5,3,0) -> #N/A | T31: =IF(AND(C31>R31, C31<=S31),"During Campaign","Before Campaign") -> #N/A | U31: =SUM(Posts_Cleaned[[#This Row],[Likes]]+Posts_Cleaned[[#This Row],[Shares]]+Posts_Cleaned[[#This Row],[Comments]]+Posts_Cleaned[[#This Row],[Clicks]]) -> 3305 | V31: =AVERAGEIF(Posts_Cleaned[[#This Row],[Period]]:T:T,"Before Campaign",Posts_Cleaned[[#This Row],[Engagement Rate ]]) -> 0.14622715 | W31: =AVERAGEIF($T$2:$T$302,"During Campaign",P31) -> 0.14683332 | X31: =(Posts_Cleaned[[#This Row],[During ]]-Posts_Cleaned[[#This Row],[Before ]])/Posts_Cleaned[[#This Row],[During ]] -> 0.0041283145 | Y31: =IFERROR(VLOOKUP(O31, 'Campaign Metadata Dataset '!$A$1:$G$5,5,0),0) -> 0 | Z31: 0 | AA31: =(W:W-V:V)/W:W -> 0.0041283145
A32: P031 | B32: Instagram | C32: 45642 | D32: Text | E32: Check out our latest text on instagram! | F32: 438 | G32: 153 | H32: 275 | I32: 3066 | J32: 2701 | K32: 282 | L32: #TeslaCoInnovation | O32: ModelYCampaign | P32: =IFERROR(((Posts_Cleaned[[#This Row],[Likes]]+Posts_Cleaned[[#This Row],[Shares]]+Posts_Cleaned[[#This Row],[Comments]])/Posts_Cleaned[[#This Row],[Impressions]]),0) -> 0.28245271 | Q32: =_xlfn.TEXTJOIN(", ", TRUE, Posts_Cleaned[[#This Row],[Hashtags Used.1]], Posts_Cleaned[[#This Row],[Hashtags Used.2]], Posts_Cleaned[[#This Row],[Hashtags Used.3]]) -> #TeslaCoInnovation | R32: =VLOOKUP(Posts_Cleaned[[#This Row],[Campaign_Name]],'Campaign Metadata Dataset '!$A$2:$B$5,2,0) -> 45566 | S32: =VLOOKUP(Posts_Cleaned[[#This Row],[Campaign_Name]],'Campaign Metadata Dataset '!$A$1:$C$5,3,0) -> 45596 | T32: =IF(AND(C32>R32, C32<=S32),"During Campaign","Before Campaign") -> Before Campaign | U32: =SUM(Posts_Cleaned[[#This Row],[Likes]]+Posts_Cleaned[[#This Row],[Shares]]+Posts_Cleaned[[#This Row],[Comments]]+Posts_Cleaned[[#This Row],[Clicks]]) -> 1148 | V32: =AVERAGEIF(Posts_Cleaned[[#This Row],[Period]]:T:T,"Before Campaign",Posts_Cleaned[[#This Row],[Engagement Rate ]]) -> 0.15913154 | W32: =AVERAGEIF($T$2:$T$302,"During Campaign",P32) -> 0.1853216 | X32: =(Posts_Cleaned[[#This Row],[During ]]-Posts_Cleaned[[#This Row],[Before ]])/Posts_Cleaned[[#This Row],[During ]] -> 0.14132221 | Y32: =IFERROR(VLOOKUP(O32, 'Campaign Metadata Dataset '!$A$1:$G$5,5,0),0) -> 200000 | Z32: =(F:F+G:G+H:H+K:K)/Y:Y -> 0.00574 | AA32: =(W:W-V:V)/W:W -> 0.14132221
A33: P032 | B33: X | C33: 45504 | D33: Carousel | E33: Check out our latest carousel on twitter! | F33: 2278 | G33: 10 | H33: 321 | I33: 13668 | J33: 12676 | K33: 275 | L33: #EVRevolution | O33: CybertruckLaunch | P33: =IFERROR(((Posts_Cleaned[[#This Row],[Likes]]+Posts_Cleaned[[#This Row],[Shares]]+Posts_Cleaned[[#This Row],[Comments]])/Posts_Cleaned[[#This Row],[Impressions]]),0) -> 0.19088382 | Q33: =_xlfn.TEXTJOIN(", ", TRUE, Posts_Cleaned[[#This Row],[Hashtags Used.1]], Posts_Cleaned[[#This Row],[Hashtags Used.2]], Posts_Cleaned[[#This Row],[Hashtags Used.3]]) -> #EVRevolution | R33: =VLOOKUP(Posts_Cleaned[[#This Row],[Campaign_Name]],'Campaign Metadata Dataset '!$A$2:$B$5,2,0) -> 45458 | S33: =VLOOKUP(Posts_Cleaned[[#This Row],[Campaign_Name]],'Campaign Metadata Dataset '!$A$1:$C$5,3,0) -> 45488 | T33: =IF(AND(C33>R33, C33<=S33),"During Campaign","Before Campaign") -> Before Campaign | U33: =SUM(Posts_Cleaned[[#This Row],[Likes]]+Posts_Cleaned[[#This Row],[Shares]]+Posts_Cleaned[[#This Row],[Comments]]+Posts_Cleaned[[#This Row],[Clicks]]) -> 2884 | V33: =AVERAGEIF(Posts_Cleaned[[#This Row],[Period]]:T:T,"Before Campaign",Posts_Cleaned[[#This Row],[Engagement Rate ]]) -> 0.15445104 | W33: =AVERAGEIF($T$2:$T$302,"During Campaign",P33) -> 0.16862724 | X33: =(Posts_Cleaned[[#This Row],[During ]]-Posts_Cleaned[[#This Row],[Before ]])/Posts_Cleaned[[#This Row],[During ]] -> 0.08406822 | Y33: =IFERROR(VLOOKUP(O33, 'Campaign Metadata Dataset '!$A$1:$G$5,5,0),0) -> 150000 | Z33: =(F:F+G:G+H:H+K:K)/Y:Y -> 0.019226667 | AA33: =(W:W-V:V)/W:W -> 0.08406822
A34: P033 | B34: Facebook | C34: 45525 | D34: Image | E34: Check out our latest image on facebook! | F34: 1407 | G34: 400 | H34: 351 | I34: 16884 | J34: 15954 | K34: 113 | L34: #TeslaCoInnovation | O34: CybertruckLaunch | P34: =IFERROR(((Posts_Cleaned[[#This Row],[Likes]]+Posts_Cleaned[[#This Row],[Shares]]+Posts_Cleaned[[#This Row],[Comments]])/Posts_Cleaned[[#This Row],[Impressions]]),0) -> 0.12781331 | Q34: =_xlfn.TEXTJOIN(", ", TRUE, Posts_Cleaned[[#This Row],[Hashtags Used.1]], Posts_Cleaned[[#This Row],[Hashtags Used.2]], Posts_Cleaned[[#This Row],[Hashtags Used.3]]) -> #TeslaCoInnovation | R34: =VLOOKUP(Posts_Cleaned[[#This Row],[Campaign_Name]],'Campaign Metadata Dataset '!$A$2:$B$5,2,0) -> 45458 | S34: =VLOOKUP(Posts_Cleaned[[#This Row],[Campaign_Name]],'Campaign Metadata Dataset '!$A$1:$C$5,3,0) -> 45488 | T34: =IF(AND(C34>R34, C34<=S34),"During Campaign","Before Campaign") -> Before Campaign | U34: =SUM(Posts_Cleaned[[#This Row],[Likes]]+Posts_Cleaned[[#This Row],[Shares]]+Posts_Cleaned[[#This Row],[Comments]]+Posts_Cleaned[[#This Row],[Clicks]]) -> 2271 | V34: =AVERAGEIF(Posts_Cleaned[[#This Row],[Period]]:T:T,"Before Campaign",Posts_Cleaned[[#This Row],[Engagement Rate ]]) -> 0.158436 | W34: =AVERAGEIF($T$2:$T$302,"During Campaign",P34) -> 0.14623979 | X34: =(Posts_Cleaned[[#This Row],[During ]]-Posts_Cleaned[[#This Row],[Before ]])/Posts_Cleaned[[#This Row],[During ]] -> -0.083398758 | Y34: =IFERROR(VLOOKUP(O34, 'Campaign Metadata Dataset '!$A$1:$G$5,5,0),0) -> 150000 | Z34: =(F:F+G:G+H:H+K:K)/Y:Y -> 0.01514 | AA34: =(W:W-V:V)/W:W -> -0.083398758
A35: P034 | B35: Facebook | C35: 45742 | D35: Text | E35: Check out our latest text on facebook! | F35: 1652 | G35: 89 | H35: 357 | I35: 29736 | J35: 28771 | K35: 215 | L35: #TeslaCoInnovation | O35: FSDUpdate | P35: =IFERROR(((Posts_Cleaned[[#This Row],[Likes]]+Posts_Cleaned[[#This Row],[Shares]]+Posts_Cleaned[[#This Row],[Comments]])/Posts_Cleaned[[#This Row],[Impressions]]),0) -> 0.07055421 | Q35: =_xlfn.TEXTJOIN(", ", TRUE, Posts_Cleaned[[#This Row],[Hashtags Used.1]], Posts_Cleaned[[#This Row],[Hashtags Used.2]], Posts_Cleaned[[#This Row],[Hashtags Used.3]]) -> #TeslaCoInnovation | R35: =VLOOKUP(Posts_Cleaned[[#This Row],[Campaign_Name]],'Campaign Metadata Dataset '!$A$2:$B$5,2,0) -> 45651 | S35: =VLOOKUP(Posts_Cleaned[[#This Row],[Campaign_Name]],'Campaign Metadata Dataset '!$A$1:$C$5,3,0) -> 45667 | T35: =IF(AND(C35>R35, C35<=S35),"During Campaign","Before Campaign") -> Before Campaign | U35: =SUM(Posts_Cleaned[[#This Row],[Likes]]+Posts_Cleaned[[#This Row],[Shares]]+Posts_Cleaned[[#This Row],[Comments]]+Posts_Cleaned[[#This Row],[Clicks]]) -> 2313 | V35: =AVERAGEIF(Posts_Cleaned[[#This Row],[Period]]:T:T,"Before Campaign",Posts_Cleaned[[#This Row],[Engagement Rate ]]) -> 0.15511748 | W35: =AVERAGEIF($T$2:$T$302,"During Campaign",P35) -> 0.14913572 | X35: =(Posts_Cleaned[[#This Row],[During ]]-Posts_Cleaned[[#This Row],[Before ]])/Posts_Cleaned[[#This Row],[During ]] -> -0.0401095 | Y35: =IFERROR(VLOOKUP(O35, 'Campaign Metadata Dataset '!$A$1:$G$5,5,0),0) -> 250000 | Z35: =(F:F+G:G+H:H+K:K)/Y:Y -> 0.009252 | AA35: =(W:W-V:V)/W:W -> -0.0401095
A36: P035 | B36: Instagram | C36: 45626 | D36: Video | E36: Check out our latest video on instagram! | F36: 3775 | G36: 16 | H36: 239 | I36: 33975 | J36: 33310 | K36: 271 | L36: #FutureOfDriving | O36: ModelYCampaign | P36: =IFERROR(((Posts_Cleaned[[#This Row],[Likes]]+Posts_Cleaned[[#This Row],[Shares]]+Posts_Cleaned[[#This Row],[Comments]])/Posts_Cleaned[[#This Row],[Impressions]]),0) -> 0.11861663 | Q36: =_xlfn.TEXTJOIN(", ", TRUE, Posts_Cleaned[[#This Row],[Hashtags Used.1]], Posts_Cleaned[[#This Row],[Hashtags Used.2]], Posts_Cleaned[[#This Row],[Hashtags Used.3]]) -> #FutureOfDriving | R36: =VLOOKUP(Posts_Cleaned[[#This Row],[Campaign_Name]],'Campaign Metadata Dataset '!$A$2:$B$5,2,0) -> 45566 | S36: =VLOOKUP(Posts_Cleaned[[#This Row],[Campaign_Name]],'Campaign Metadata Dataset '!$A$1:$C$5,3,0) -> 45596 | T36: =IF(AND(C36>R36, C36<=S36),"During Campaign","Before Campaign") -> Before Campaign | U36: =SUM(Posts_Cleaned[[#This Row],[Likes]]+Posts_Cleaned[[#This Row],[Shares]]+Posts_Cleaned[[#This Row],[Comments]]+Posts_Cleaned[[#This Row],[Clicks]]) -> 4301 | V36: =AVERAGEIF(Posts_Cleaned[[#This Row],[Period]]:T:T,"Before Campaign",Posts_Cleaned[[#This Row],[Engagement Rate ]]) -> 0.14953215 | W36: =AVERAGEIF($T$2:$T$302,"During Campaign",P36) -> 0.16157667 | X36: =(Posts_Cleaned[[#This Row],[During ]]-Posts_Cleaned[[#This Row],[Before ]])/Posts_Cleaned[[#This Row],[During ]] -> 0.07454365 | Y36: =IFERROR(VLOOKUP(O36, 'Campaign Metadata Dataset '!$A$1:$G$5,5,0),0) -> 200000 | Z36: =(F:F+G:G+H:H+K:K)/Y:Y -> 0.021505 | AA36: =(W:W-V:V)/W:W -> 0.07454365
A37: P036 | B37: Instagram | C37: 45766 | D37: Story | E37: Check out our latest story on instagram! | F37: 4518 | G37: 285 | H37: 383 | I37: 67770 | J37: 67621 | K37: 31 | L37: #EVRevolution | O37: ModelYCampaign | P37: =IFERROR(((Posts_Cleaned[[#This Row],[Likes]]+Posts_Cleaned[[#This Row],[Shares]]+Posts_Cleaned[[#This Row],[Comments]])/Posts_Cleaned[[#This Row],[Impressions]]),0) -> 0.076523535 | Q37: =_xlfn.TEXTJOIN(", ", TRUE, Posts_Cleaned[[#This Row],[Hashtags Used.1]], Posts_Cleaned[[#This Row],[Hashtags Used.2]], Posts_Cleaned[[#This Row],[Hashtags Used.3]]) -> #EVRevolution | R37: =VLOOKUP(Posts_Cleaned[[#This Row],[Campaign_Name]],'Campaign Metadata Dataset '!$A$2:$B$5,2,0) -> 45566 | S37: =VLOOKUP(Posts_Cleaned[[#This Row],[Campaign_Name]],'Campaign Metadata Dataset '!$A$1:$C$5,3,0) -> 45596 | T37: =IF(AND(C37>R37, C37<=S37),"During Campaign","Before Campaign") -> Before Campaign | U37: =SUM(Posts_Cleaned[[#This Row],[Likes]]+Posts_Cleaned[[#This Row],[Shares]]+Posts_Cleaned[[#This Row],[Comments]]+Posts_Cleaned[[#This Row],[Clicks]]) -> 5217 | V37: =AVERAGEIF(Posts_Cleaned[[#This Row],[Period]]:T:T,"Before Campaign",Posts_Cleaned[[#This Row],[Engagement Rate ]]) -> 0.15223713 | W37: =AVERAGEIF($T$2:$T$302,"During Campaign",P37) -> 0.13705361 | X37: =(Posts_Cleaned[[#This Row],[During ]]-Posts_Cleaned[[#This Row],[Before ]])/Posts_Cleaned[[#This Row],[During ]] -> -0.11078523 | Y37: =IFERROR(VLOOKUP(O37, 'Campaign Metadata Dataset '!$A$1:$G$5,5,0),0) -> 200000 | Z37: =(F:F+G:G+H:H+K:K)/Y:Y -> 0.026085 | AA37: =(W:W-V:V)/W:W -> -0.11078523
A38: P037 | B38: Facebook | C38: 45663 | D38: Carousel | E38: Check out our latest carousel on facebook! | F38: 3024 | G38: 925 | H38: 350 | I38: 24192 | J38: 23518 | K38: 36 | L38: #EVRevolution | O38: ModelYCampaign | P38: =IFERROR(((Posts_Cleaned[[#This Row],[Likes]]+Posts_Cleaned[[#This Row],[Shares]]+Posts_Cleaned[[#This Row],[Comments]])/Posts_Cleaned[[#This Row],[Impressions]]),0) -> 0.17770337 | Q38: =_xlfn.TEXTJOIN(", ", TRUE, Posts_Cleaned[[#This Row],[Hashtags Used.1]], Posts_Cleaned[[#This Row],[Hashtags Used.2]], Posts_Cleaned[[#This Row],[Hashtags Used.3]]) -> #EVRevolution | R38: =VLOOKUP(Posts_Cleaned[[#This Row],[Campaign_Name]],'Campaign Metadata Dataset '!$A$2:$B$5,2,0) -> 45566 | S38: =VLOOKUP(Posts_Cleaned[[#This Row],[Campaign_Name]],'Campaign Metadata Dataset '!$A$1:$C$5,3,0) -> 45596 | T38: =IF(AND(C38>R38, C38<=S38),"During Campaign","Before Campaign") -> Before Campaign | U38: =SUM(Posts_Cleaned[[#This Row],[Likes]]+Posts_Cleaned[[#This Row],[Shares]]+Posts_Cleaned[[#This Row],[Comments]]+Posts_Cleaned[[#This Row],[Clicks]]) -> 4335 | V38: =AVERAGEIF(Posts_Cleaned[[#This Row],[Period]]:T:T,"Before Campaign",Posts_Cleaned[[#This Row],[Engagement Rate ]]) -> 0.15360062 | W38: =AVERAGEIF($T$2:$T$302,"During Campaign",P38) -> 0.17518736 | X38: =(Posts_Cleaned[[#This Row],[During ]]-Posts_Cleaned[[#This Row],[Before ]])/Posts_Cleaned[[#This Row],[During ]] -> 0.12322089 | Y38: =IFERROR(VLOOKUP(O38, 'Campaign Metadata Dataset '!$A$1:$G$5,5,0),0) -> 200000 | Z38: =(F:F+G:G+H:H+K:K)/Y:Y -> 0.021675 | AA38: =(W:W-V:V)/W:W -> 0.12322089
